Traceback (most recent call last):
  File "/Applications/Eclipse_2019-06.app/Contents/workspace/meteorologicalDataScrapingApp/mainJobBatch/taskManage/task/base/mdScrapingTask.py", line 58, in jobControl
    md_scraping_service.updateFileCreateStatus(self.general_group_key, self.processing_general_key)
  File "/Applications/Eclipse_2019-06.app/Contents/workspace/meteorologicalDataScrapingApp/mainJobBatch/taskManage/serviceBase/Impl/mdScrapingTaskServiceImpl.py", line 147, in updateFileCreateStatus
    process_param = self.getResultFileNumAndJobNum(cur)
  File "/Applications/Eclipse_2019-06.app/Contents/workspace/meteorologicalDataScrapingApp/mainJobBatch/taskManage/service/Impl/newFileCreateTaskServiceImpl.py", line 48, in getResultFileNumAndJobNum
    job_num = select_job_que_data_result['job_num_list'][0]
IndexError: list index out of range
Traceback (most recent call last):
  File "/Applications/Eclipse_2019-06.app/Contents/workspace/meteorologicalDataScrapingApp/mainJobBatch/taskManage/task/base/mdScrapingTask.py", line 56, in jobControl
    md_scraping_service.scrapingTask()
  File "/Applications/Eclipse_2019-06.app/Contents/workspace/meteorologicalDataScrapingApp/mainJobBatch/taskManage/serviceBase/Impl/mdScrapingTaskServiceImpl.py", line 194, in scrapingTask
    if self.countJob(cur):
  File "/Applications/Eclipse_2019-06.app/Contents/workspace/meteorologicalDataScrapingApp/mainJobBatch/taskManage/service/Impl/newFileCreateTaskServiceImpl.py", line 88, in countJob
    return self.new_file_create_dao.jadgeJobNumStock(cur, self.user_id)
  File "/Applications/Eclipse_2019-06.app/Contents/workspace/meteorologicalDataScrapingApp/mainJobBatch/taskManage/dao/daoImple/newFileCreateDaoImple.py", line 39, in jadgeJobNumStock
    print(rows.length)
AttributeError: 'list' object has no attribute 'length'
Traceback (most recent call last):
  File "/Users/nishidayuki/Library/Python/3.8/lib/python/site-packages/mysql/connector/network.py", line 161, in send_plain
    self.sock.sendall(packet)
  File "/Applications/Xcode.app/Contents/Developer/Library/Frameworks/Python3.framework/Versions/3.8/lib/python3.8/ssl.py", line 1207, in sendall
    return super().sendall(data, flags)
OSError: [Errno 9] Bad file descriptor

During handling of the above exception, another exception occurred:

Traceback (most recent call last):
  File "/Applications/Eclipse_2019-06.app/Contents/workspace/meteorologicalDataScrapingApp/mainJobBatch/taskManage/task/base/mdScrapingTask.py", line 56, in jobControl
    md_scraping_service.scrapingTask()
  File "/Applications/Eclipse_2019-06.app/Contents/workspace/meteorologicalDataScrapingApp/mainJobBatch/taskManage/serviceBase/Impl/mdScrapingTaskServiceImpl.py", line 194, in scrapingTask
    if self.countJob(cur):
  File "/Applications/Eclipse_2019-06.app/Contents/workspace/meteorologicalDataScrapingApp/mainJobBatch/taskManage/service/Impl/newFileCreateTaskServiceImpl.py", line 88, in countJob
    return self.new_file_create_dao.jadgeJobNumStock(cur, self.user_id)
  File "/Applications/Eclipse_2019-06.app/Contents/workspace/meteorologicalDataScrapingApp/mainJobBatch/taskManage/dao/daoImple/newFileCreateDaoImple.py", line 37, in jadgeJobNumStock
    cur.execute(select_user_job_num)
  File "/Users/nishidayuki/Library/Python/3.8/lib/python/site-packages/mysql/connector/cursor.py", line 568, in execute
    self._handle_result(self._connection.cmd_query(stmt))
  File "/Users/nishidayuki/Library/Python/3.8/lib/python/site-packages/mysql/connector/connection.py", line 854, in cmd_query
    result = self._handle_result(self._send_cmd(ServerCmd.QUERY, query))
  File "/Users/nishidayuki/Library/Python/3.8/lib/python/site-packages/mysql/connector/connection.py", line 501, in _send_cmd
    self._socket.send(
  File "/Users/nishidayuki/Library/Python/3.8/lib/python/site-packages/mysql/connector/network.py", line 163, in send_plain
    raise errors.OperationalError(
mysql.connector.errors.OperationalError: 2055: Lost connection to MySQL server at 'localhost:3306', system error: 9 Bad file descriptor
Traceback (most recent call last):
  File "/Applications/Eclipse_2019-06.app/Contents/workspace/meteorologicalDataScrapingApp/mainJobBatch/taskManage/task/base/mdScrapingTask.py", line 56, in jobControl
    md_scraping_service.scrapingTask()
  File "/Applications/Eclipse_2019-06.app/Contents/workspace/meteorologicalDataScrapingApp/mainJobBatch/taskManage/serviceBase/Impl/mdScrapingTaskServiceImpl.py", line 194, in scrapingTask
    if self.countJob(cur):
  File "/Applications/Eclipse_2019-06.app/Contents/workspace/meteorologicalDataScrapingApp/mainJobBatch/taskManage/service/Impl/newFileCreateTaskServiceImpl.py", line 88, in countJob
    return self.new_file_create_dao.jadgeJobNumStock(cur, self.user_id)
  File "/Applications/Eclipse_2019-06.app/Contents/workspace/meteorologicalDataScrapingApp/mainJobBatch/taskManage/dao/daoImple/newFileCreateDaoImple.py", line 39, in jadgeJobNumStock
    cur.execute(select_all)
  File "/Users/nishidayuki/Library/Python/3.8/lib/python/site-packages/mysql/connector/cursor.py", line 568, in execute
    self._handle_result(self._connection.cmd_query(stmt))
  File "/Users/nishidayuki/Library/Python/3.8/lib/python/site-packages/mysql/connector/connection.py", line 854, in cmd_query
    result = self._handle_result(self._send_cmd(ServerCmd.QUERY, query))
  File "/Users/nishidayuki/Library/Python/3.8/lib/python/site-packages/mysql/connector/connection.py", line 664, in _handle_result
    raise errors.get_exception(packet)
mysql.connector.errors.ProgrammingError: 1064 (42000): You have an error in your SQL syntax; check the manual that corresponds to your MySQL server version for the right syntax to use near 'QUERY CACHE' at line 1
Traceback (most recent call last):
  File "/Applications/Eclipse_2019-06.app/Contents/workspace/meteorologicalDataScrapingApp/mainJobBatch/taskManage/task/base/mdScrapingTask.py", line 56, in jobControl
    md_scraping_service.scrapingTask()
  File "/Applications/Eclipse_2019-06.app/Contents/workspace/meteorologicalDataScrapingApp/mainJobBatch/taskManage/serviceBase/Impl/mdScrapingTaskServiceImpl.py", line 194, in scrapingTask
    if self.countJob(cur):
  File "/Applications/Eclipse_2019-06.app/Contents/workspace/meteorologicalDataScrapingApp/mainJobBatch/taskManage/service/Impl/newFileCreateTaskServiceImpl.py", line 88, in countJob
    return self.new_file_create_dao.jadgeJobNumStock(cur, self.user_id)
  File "/Applications/Eclipse_2019-06.app/Contents/workspace/meteorologicalDataScrapingApp/mainJobBatch/taskManage/dao/daoImple/newFileCreateDaoImple.py", line 39, in jadgeJobNumStock
    cur.execute(select_all)
  File "/Users/nishidayuki/Library/Python/3.8/lib/python/site-packages/mysql/connector/cursor.py", line 568, in execute
    self._handle_result(self._connection.cmd_query(stmt))
  File "/Users/nishidayuki/Library/Python/3.8/lib/python/site-packages/mysql/connector/connection.py", line 854, in cmd_query
    result = self._handle_result(self._send_cmd(ServerCmd.QUERY, query))
  File "/Users/nishidayuki/Library/Python/3.8/lib/python/site-packages/mysql/connector/connection.py", line 664, in _handle_result
    raise errors.get_exception(packet)
mysql.connector.errors.ProgrammingError: 1064 (42000): You have an error in your SQL syntax; check the manual that corresponds to your MySQL server version for the right syntax to use near 'QUERY CACHE' at line 1
Traceback (most recent call last):
  File "/Applications/Eclipse_2019-06.app/Contents/workspace/meteorologicalDataScrapingApp/mainJobBatch/taskManage/task/base/mdScrapingTask.py", line 56, in jobControl
    md_scraping_service.scrapingTask()
  File "/Applications/Eclipse_2019-06.app/Contents/workspace/meteorologicalDataScrapingApp/mainJobBatch/taskManage/serviceBase/Impl/mdScrapingTaskServiceImpl.py", line 194, in scrapingTask
    if self.countJob(cur):
  File "/Applications/Eclipse_2019-06.app/Contents/workspace/meteorologicalDataScrapingApp/mainJobBatch/taskManage/service/Impl/newFileCreateTaskServiceImpl.py", line 88, in countJob
    return self.new_file_create_dao.jadgeJobNumStock(cur, self.user_id)
  File "/Applications/Eclipse_2019-06.app/Contents/workspace/meteorologicalDataScrapingApp/mainJobBatch/taskManage/dao/daoImple/newFileCreateDaoImple.py", line 39, in jadgeJobNumStock
    cur.execute(select_all)
  File "/Users/nishidayuki/Library/Python/3.8/lib/python/site-packages/mysql/connector/cursor.py", line 568, in execute
    self._handle_result(self._connection.cmd_query(stmt))
  File "/Users/nishidayuki/Library/Python/3.8/lib/python/site-packages/mysql/connector/connection.py", line 854, in cmd_query
    result = self._handle_result(self._send_cmd(ServerCmd.QUERY, query))
  File "/Users/nishidayuki/Library/Python/3.8/lib/python/site-packages/mysql/connector/connection.py", line 664, in _handle_result
    raise errors.get_exception(packet)
mysql.connector.errors.ProgrammingError: 1064 (42000): You have an error in your SQL syntax; check the manual that corresponds to your MySQL server version for the right syntax to use near 'QUERY CACHE' at line 1
Traceback (most recent call last):
  File "/Applications/Eclipse_2019-06.app/Contents/workspace/meteorologicalDataScrapingApp/mainJobBatch/taskManage/task/base/mdScrapingTask.py", line 56, in jobControl
    md_scraping_service.scrapingTask()
  File "/Applications/Eclipse_2019-06.app/Contents/workspace/meteorologicalDataScrapingApp/mainJobBatch/taskManage/serviceBase/Impl/mdScrapingTaskServiceImpl.py", line 194, in scrapingTask
    if self.countJob(cur):
  File "/Applications/Eclipse_2019-06.app/Contents/workspace/meteorologicalDataScrapingApp/mainJobBatch/taskManage/service/Impl/newFileCreateTaskServiceImpl.py", line 88, in countJob
    return self.new_file_create_dao.jadgeJobNumStock(cur, self.user_id)
  File "/Applications/Eclipse_2019-06.app/Contents/workspace/meteorologicalDataScrapingApp/mainJobBatch/taskManage/dao/daoImple/newFileCreateDaoImple.py", line 41, in jadgeJobNumStock
    cur.execute(select_all)
  File "/Users/nishidayuki/Library/Python/3.8/lib/python/site-packages/mysql/connector/cursor.py", line 568, in execute
    self._handle_result(self._connection.cmd_query(stmt))
  File "/Users/nishidayuki/Library/Python/3.8/lib/python/site-packages/mysql/connector/connection.py", line 854, in cmd_query
    result = self._handle_result(self._send_cmd(ServerCmd.QUERY, query))
  File "/Users/nishidayuki/Library/Python/3.8/lib/python/site-packages/mysql/connector/connection.py", line 664, in _handle_result
    raise errors.get_exception(packet)
mysql.connector.errors.ProgrammingError: 1064 (42000): You have an error in your SQL syntax; check the manual that corresponds to your MySQL server version for the right syntax to use near 'QUERY CACHE' at line 1
